Workbook

Sheet Consolidated
A1: Row_ID | B1: Species_Name | C1: Genus | D1: Sex | E1: Has_Frequency | F1: Freq_Min_Hz | G1: Freq_Max_Hz | H1: Freq_Mean_Hz | I1: Freq_SD_Hz | J1: Frequency_Basis | K1: Measurement_Conditions | L1: Vector_Status | M1: Disease_Association | N1: India_Relevance | O1: Evidence_Level | P1: Source | Q1: Study_Year | R1: PMID_DOI | S1: Source_URL | T1: From_Version | U1: Notes
A2: R001 | B2: Aedes aegypti | C2: Aedes | D2: Female | E2: Yes | F2: 460 | G2: 664 | J2: Published values across studies | K2: Not recorded in v1 | L2: Established vector | M2: Dengue; Chikungunya; Zika; Yellow fever | N2: Not recorded in v1 | O2: High | P2: Peer-reviewed acoustic studies + WHO | Q2: Not recorded in v1 | R2: Not recorded in v1 | S2: https://academic.oup.com/aesa/article/115/1/113/6409746 | T2: v1 (33-row) | U2: Frequency varies by study and experimental conditions.
A3: R002 | B3: Aedes aegypti | C3: Aedes | D3: Female | E3: Yes | H3: 463.07 | I3: 3.22 | J3: Fundamental frequency (F0) | K3: Lab-reared, India field-collected colonies, sound-recording device (Mandal et al. 2024) | L3: Established vector | M3: Dengue; Chikungunya; Zika; Yellow fever | N3: Yes - recognized dengue/chikungunya vector under NCVBDC-monitored NVBDCP | O3: HIGH | P3: Mandal et al. 2024 (Acta Tropica, S1) | Q3: 2024 | R3: 38642695 | S3: https://www.sciencedirect.com/science/article/abs/pii/S0001706X24001049 | T3: v2 (26-row) | U3: India-collected value. See SP001b/SP001c for other source-specific frequency values for the same species/sex - do not average across rows.
A4: R003 | B4: Aedes aegypti | C4: Aedes | D4: Female | E4: Yes | H4: 498.1 | J4: Mean wingbeat frequency | K4: Lab colony, Florida USA, infrared sensor array, 23.0 +/- 0.5 degC, 60% RH (Kim et al. 2021) | L4: Established vector | M4: Dengue; Chikungunya; Zika; Yellow fever | N4: Yes (species-level; this specific measurement is from a US lab colony, not an Indian population) | O4: HIGH | P4: Kim et al. 2021 (Scientific Reports, S2) | Q4: 2021 | R4: 10.1038/s41598-021-89644-z | S4: https://www.nature.com/articles/s41598-021-89644-z | T4: v2 (26-row) | U4: Temperature explicitly reported: 23.0 degC. Compare to SP001c (32.6 degC, higher value) - illustrates temperature dependence of wingbeat frequency, exactly as flagged by the source paper's own discussion.
A5: R004 | B5: Aedes aegypti | C5: Aedes | D5: Female | E5: Yes | H5: 664 | J5: Free-flight mating-swarm flight tone | K5: Free-flight mating swarms, Thailand, field, 32.6 +/- 0.5 degC (Cator et al. 2011, cited via Kim et al. 2021) | L5: Established vector | M5: Dengue; Chikungunya; Zika; Yellow fever | N5: Yes (species-level) | O5: MEDIUM | P5: Cator, Arthur, Ponlawat & Harrington 2011 (S3) - value taken from citation within Kim et al. 2021 (S2), primary paper not directly fetched | Q5: 2011 | R5: 10.1603/ME11019 | S5: Secondary citation via S2 (see Sources sheet) | T5: v2 (26-row) | U5: 28.6% higher than Kim et al. 2021's lab value (498.1 Hz); Kim et al. attribute the difference to higher field temperature (32.6 vs 23.0 degC) and/or differing recording devices (microphone vs infrared sensor) - do not treat either value as the 'true' frequency for the species.
A6: R005 | B6: Aedes aegypti | C6: Aedes | D6: Male | E6: Yes | F6: 711 | G6: 982 | J6: Published range | K6: Not recorded in v1 | L6: Established vector | M6: Dengue; Chikungunya; Zika; Yellow fever | N6: Not recorded in v1 | O6: High | P6: Peer-reviewed acoustic studies + WHO | Q6: Not recorded in v1 | R6: Not recorded in v1 | S6: https://academic.oup.com/aesa/article/115/1/113/6409746 | T6: v1 (33-row) | U6: Male frequency is substantially higher than female frequency.
A7: R006 | B7: Aedes aegypti | C7: Aedes | D7: Male | E7: Yes | H7: 800 | J7: Approximate wingbeat frequency (free flight, high-speed video) | K7: Tethered-free flight chamber, high-speed video at 13,000 fps, unmated males 4-7 days old (arXiv preprint, S5) - NOT peer-reviewed | L7: Established vector | M7: Dengue; Chikungunya; Zika; Yellow fever (male mosquitoes do not bite/transmit disease themselves, but species is an established vector via females) | N7: Yes (species-level) | O7: LOW | P7: arXiv preprint 1205.5260 (S5) - LOW CONFIDENCE, preprint only | Q7: Not confirmed (preprint) | R7: Not applicable (preprint) | S7: https://arxiv.org/pdf/1205.5260 | T7: v2 (26-row) | U7: Included ONLY because no peer-reviewed male Ae. aegypti Hz figure could be retrieved in this research pass; Arthur et al. 2014 (S4, peer-reviewed) confirms qualitatively that male fundamental frequency is higher than female and modulated over a wider range, but its exact Hz table was not accessible (paywalled). Treat this row as provisional.
A8: R007 | B8: Aedes albopictus | C8: Aedes | D8: Female | E8: Yes | F8: 462 | G8: 544 | J8: Published values across studies | K8: Not recorded in v1 | L8: Established vector | M8: Dengue; Chikungunya; Zika | N8: Not recorded in v1 | O8: High | P8: Peer-reviewed acoustic studies + WHO | Q8: Not recorded in v1 | R8: Not recorded in v1 | S8: https://academic.oup.com/aesa/article/115/1/113/6409746 | T8: v1 (33-row) | U8: Published values overlap with other species.
A9: R008 | B9: Aedes albopictus | C9: Aedes | D9: Female | E9: Yes | H9: 510.9 | I9: 22.03 | J9: Fundamental frequency (F0) | K9: India field-collected, sound-recording device (Mandal et al. 2024) | L9: Documented vector | M9: Dengue; Chikungunya | N9: Yes - explicitly identified as the dengue vector in an Indian field vector-composition study, though present at very low relative abundance (0.05%) in that survey | O9: HIGH | P9: Mandal et al. 2024 (Acta Tropica, S1) | Q9: 2024 | R9: 38642695 | S9: https://www.sciencedirect.com/science/article/abs/pii/S0001706X24001049 | T9: v2 (26-row) | U9: nan
A10: R009 | B10: Aedes albopictus | C10: Aedes | D10: Male | E10: Yes | F10: 724 | G10: 903 | J10: Published range | K10: Not recorded in v1 | L10: Established vector | M10: Dengue; Chikungunya; Zika | N10: Not recorded in v1 | O10: High | P10: Peer-reviewed acoustic studies | Q10: Not recorded in v1 | R10: Not recorded in v1 | S10: https://academic.oup.com/aesa/article/115/1/113/6409746 | T10: v1 (33-row) | U10: Male frequency depends on study and conditions.
A11: R010 | B11: Aedes vittatus | C11: Aedes | D11: Female | E11: Yes | F11: 567.51 | G11: 567.51 | H11: 567.51 | I11: 3.82 | J11: Mean ± SD | K11: Not recorded in v1 | L11: Documented/experimental vector evidence | M11: Dengue; Chikungunya; Zika; Yellow fever; experimental competence reported for several viruses | N11: Not recorded in v1 | O11: Medium | P11: 2024 India acoustic study + vector-competence literature | Q11: Not recorded in v1 | R11: Not recorded in v1 | S11: https://www.sciencedirect.com/science/article/pii/S0001706X24001049 | T11: v1 (33-row) | U11: Experimental competence is not equivalent to principal epidemiological vector status.
A12: R011 | B12: Aedes vittatus | C12: Aedes | D12: Female | E12: Yes | H12: 567.51 | I12: 3.82 | J12: Fundamental frequency (F0) | K12: India field-collected, sound-recording device (Mandal et al. 2024) - reported as the highest F0 of the 19 species studied | L12: Evidence insufficient | M12: Not found | N12: Species recorded in India (S1); disease/vector role not verified in this research pass | O12: MEDIUM | P12: Mandal et al. 2024 (Acta Tropica, S1) | Q12: 2024 | R12: 38642695 | S12: https://www.sciencedirect.com/science/article/abs/pii/S0001706X24001049 | T12: v2 (26-row) | U12: Ae. vittatus is reported elsewhere in the literature as a sylvatic yellow-fever/chikungunya-associated species in parts of Africa, but no such claim is included here because it was not independently verified with a primary source in this research pass. Do not add without a checked citation.
A13: R012 | B13: Anopheles albimanus | C13: Anopheles | D13: Female | E13: Yes | F13: 369 | G13: 430 | J13: Published range | K13: Not recorded in v1 | L13: Established vector | M13: Malaria | N13: Not recorded in v1 | O13: High | P13: Peer-reviewed acoustic studies | Q13: Not recorded in v1 | R13: Not recorded in v1 | S13: https://academic.oup.com/aesa/article/115/1/113/6409746 | T13: v1 (33-row) | U13: Regional malaria vector in the Americas.
A14: R013 | B14: Anopheles albimanus | C14: Anopheles | D14: Male | E14: Yes | F14: 524 | G14: 714 | J14: Published range | K14: Not recorded in v1 | L14: Established vector | M14: Malaria | N14: Not recorded in v1 | O14: High | P14: Peer-reviewed acoustic studies | Q14: Not recorded in v1 | R14: Not recorded in v1 | S14: https://academic.oup.com/aesa/article/115/1/113/6409746 | T14: v1 (33-row) | U14: Male reference range.
A15: R014 | B15: Anopheles annularis | C15: Anopheles | D15: Not reported | E15: No | J15: Not found | K15: Not found | L15: Documented vector | M15: Malaria | N15: Yes - named as a malaria vector in an Indian field vector-composition study | O15: MEDIUM | P15: Not found - no acoustic/wingbeat frequency study located for this species in this research pass | Q15: 2011 | R15: Not confirmed | S15: https://pmc.ncbi.nlm.nih.gov/articles/PMC4017167/ | T15: v2 (26-row) | U15: No wingbeat/acoustic frequency data located for this species in this research pass - do not infer a value from congeners.
A16: R015 | B16: Anopheles arabiensis | C16: Anopheles | D16: Female | E16: Yes | F16: 489 | G16: 489 | H16: 489 | J16: Published value | K16: Not recorded in v1 | L16: Established vector | M16: Malaria | N16: Not recorded in v1 | O16: High | P16: Peer-reviewed acoustic studies | Q16: Not recorded in v1 | R16: Not recorded in v1 | S16: https://academic.oup.com/aesa/article/115/1/113/6409746 | T16: v1 (33-row) | U16: Major African malaria vector.
A17: R016 | B17: Anopheles arabiensis | C17: Anopheles | D17: Male | E17: Yes | F17: 763 | G17: 763 | H17: 763 | J17: Published value | K17: Not recorded in v1 | L17: Established vector | M17: Malaria | N17: Not recorded in v1 | O17: High | P17: Peer-reviewed acoustic studies | Q17: Not recorded in v1 | R17: Not recorded in v1 | S17: https://academic.oup.com/aesa/article/115/1/113/6409746 | T17: v1 (33-row) | U17: Male reference frequency.
A18: R017 | B18: Anopheles barbirostris | C18: Anopheles | D18: Not reported | E18: No | J18: Not found | K18: Not found | L18: Documented vector | M18: Japanese encephalitis | N18: Yes - named as a JE vector in an Indian field vector-composition study | O18: MEDIUM | P18: Not found - no acoustic/wingbeat frequency study located for this species in this research pass | Q18: 2011 | R18: Not confirmed | S18: https://pmc.ncbi.nlm.nih.gov/articles/PMC4017167/ | T18: v2 (26-row) | U18: No wingbeat/acoustic frequency data located for this species in this research pass - do not infer a value from congeners.
A19: R018 | B19: Anopheles crawfordi | C19: Anopheles | D19: Female | E19: Yes | F19: 295.29 | G19: 338.29 | H19: 320.27 | J19: Range + mean | K19: Not recorded in v1 | L19: No major human-disease vector role identified | M19: No major human-disease vector association identified in reviewed sources | N19: Not recorded in v1 | O19: Medium | P19: 2025 India acoustic study | Q19: Not recorded in v1 | R19: Not recorded in v1 | S19: https://pmc.ncbi.nlm.nih.gov/articles/PMC12049413/ | T19: v1 (33-row) | U19: Included primarily as an acoustic reference species.
A20: R019 | B20: Anopheles culicifacies | C20: Anopheles | D20: Not reported | E20: No | J20: Not found | K20: Not found | L20: Documented vector | M20: Malaria | N20: Yes - named as a malaria vector in an Indian field vector-composition study (village survey around a military station) | O20: MEDIUM | P20: Not found - no acoustic/wingbeat frequency study located for this species in this research pass | Q20: 2011 | R20: Not confirmed | S20: https://pmc.ncbi.nlm.nih.gov/articles/PMC4017167/ | T20: v2 (26-row) | U20: No wingbeat/acoustic frequency data located for this species in this research pass - do not infer a value from congeners.
A21: R020 | B21: Anopheles culiciformis | C21: Anopheles | D21: Female | E21: Yes | F21: 269.09 | G21: 269.09 | H21: 269.09 | I21: 2.96 | J21: Mean ± SD | K21: Not recorded in v1 | L21: No major human-disease vector role identified | M21: No major human-disease vector association identified in reviewed sources | N21: Not recorded in v1 | O21: Medium | P21: 2024 India acoustic study | Q21: Not recorded in v1 | R21: Not recorded in v1 | S21: https://www.sciencedirect.com/science/article/pii/S0001706X24001049 | T21: v1 (33-row) | U21: Included primarily as an acoustic reference species.
A22: R021 | B22: Anopheles culiciformis | C22: Anopheles | D22: Female | E22: Yes | H22: 269.09 | I22: 2.96 | J22: Fundamental frequency (F0) | K22: India field-collected, sound-recording device (Mandal et al. 2024) - reported as the LOWEST F0 of the 19 species studied | L22: Evidence insufficient | M22: Not found | N22: Species recorded in India (S1); disease/vector role not verified in this research pass | O22: MEDIUM | P22: Mandal et al. 2024 (Acta Tropica, S1) | Q22: 2024 | R22: 38642695 | S22: https://www.sciencedirect.com/science/article/abs/pii/S0001706X24001049 | T22: v2 (26-row) | U22: nan
A23: R022 | B23: Anopheles darlingi | C23: Anopheles | D23: Female | E23: Yes | F23: 362 | G23: 456 | J23: Published range | K23: Not recorded in v1 | L23: Established vector | M23: Malaria | N23: Not recorded in v1 | O23: High | P23: Peer-reviewed acoustic studies | Q23: Not recorded in v1 | R23: Not recorded in v1 | S23: https://academic.oup.com/aesa/article/115/1/113/6409746 | T23: v1 (33-row) | U23: Major malaria vector in tropical South America.
A24: R023 | B24: Anopheles darlingi | C24: Anopheles | D24: Male | E24: Yes | F24: 553 | G24: 709 | J24: Published range | K24: Not recorded in v1 | L24: Established vector | M24: Malaria | N24: Not recorded in v1 | O24: High | P24: Peer-reviewed acoustic studies | Q24: Not recorded in v1 | R24: Not recorded in v1 | S24: https://academic.oup.com/aesa/article/115/1/113/6409746 | T24: v1 (33-row) | U24: Male reference range.
A25: R024 | B25: Anopheles elegans | C25: Anopheles | D25: Female | E25: Yes | F25: 461.87 | G25: 461.87 | H25: 461.87 | I25: 3.31 | J25: Mean ± SD | K25: Not recorded in v1 | L25: No major human-disease vector role identified | M25: No major human-disease vector association identified in reviewed sources | N25: Not recorded in v1 | O25: Medium | P25: 2024 India acoustic study | Q25: Not recorded in v1 | R25: Not recorded in v1 | S25: https://www.sciencedirect.com/science/article/pii/S0001706X24001049 | T25: v1 (33-row) | U25: Included primarily as an acoustic reference species.
A26: R025 | B26: Anopheles elegans | C26: Anopheles | D26: Female | E26: Yes | H26: 461.87 | I26: 3.31 | J26: Fundamental frequency (F0) | K26: India field-collected, sound-recording device (Mandal et al. 2024) | L26: Evidence insufficient | M26: Not found | N26: Species recorded in India (S1); disease/vector role not verified in this research pass | O26: MEDIUM | P26: Mandal et al. 2024 (Acta Tropica, S1) | Q26: 2024 | R26: 38642695 | S26: https://www.sciencedirect.com/science/article/abs/pii/S0001706X24001049 | T26: v2 (26-row) | U26: nan
A27: R026 | B27: Anopheles gambiae | C27: Anopheles | D27: Not reported | E27: No | J27: Not found | K27: Not found | L27: Established vector | M27: Malaria | N27: No - primary Afrotropical malaria vector; not an established Indian vector species in sources reviewed | O27: MEDIUM | P27: Not found - no acoustic/wingbeat frequency study located for this species in this research pass (note: species is included in the 2024 India acoustic study's 19-species list per its abstract count of 7 Anopheles species, but this specific species' value was not among the 9 explicitly quoted in the accessible abstract text) | Q27: Not confirmed | R27: Not confirmed | S27: https://www.sciencedirect.com/topics/immunology-and-microbiology/anopheles-gambiae ; https://www.ncbi.nlm.nih.gov/pmc/articles/PMC5354110/ | T27: v2 (26-row) | U27: Malaria-vector status here rests partly on a tertiary topic-summary source (S10), not a primary peer-reviewed study fetched in this pass - flag for stronger sourcing (e.g., WHO malaria vector pages) before production use.
A28: R027 | B28: Anopheles gambiae s.s. | C28: Anopheles | D28: Female | E28: Yes | F28: 490 | G28: 490 | H28: 490 | J28: Published value | K28: Not recorded in v1 | L28: Established vector | M28: Malaria | N28: Not recorded in v1 | O28: High | P28: Peer-reviewed acoustic studies | Q28: Not recorded in v1 | R28: Not recorded in v1 | S28: https://academic.oup.com/aesa/article/115/1/113/6409746 | T28: v1 (33-row) | U28: Species-complex taxonomy should be handled carefully.
A29: R028 | B29: Anopheles gambiae s.s. | C29: Anopheles | D29: Male | E29: Yes | F29: 779 | G29: 793 | J29: Published range | K29: Not recorded in v1 | L29: Established vector | M29: Malaria | N29: Not recorded in v1 | O29: High | P29: Peer-reviewed acoustic studies | Q29: Not recorded in v1 | R29: Not recorded in v1 | S29: https://academic.oup.com/aesa/article/115/1/113/6409746 | T29: v1 (33-row) | U29: Species-complex taxonomy can affect labels.
A30: R029 | B30: Anopheles philippinensis / Anopheles nivipes | C30: Anopheles | D30: Not reported | E30: No | J30: Not found | K30: Not found | L30: Documented vector | M30: Malaria | N30: Yes - reported as the most abundant malaria-vector taxon (2.05%) in an Indian field vector-composition study | O30: MEDIUM | P30: Not found - no acoustic/wingbeat frequency study located for this species in this research pass | Q30: 2011 | R30: Not confirmed | S30: https://pmc.ncbi.nlm.nih.gov/articles/PMC4017167/ | T30: v2 (26-row) | U30: No wingbeat/acoustic frequency data located for this species in this research pass - do not infer a value from congeners.
A31: R030 | B31: Anopheles stephensi | C31: Anopheles | D31: Female | E31: Yes | F31: 423 | G31: 423 | H31: 423 | J31: Published value | K31: Not recorded in v1 | L31: Established vector | M31: Malaria | N31: Not recorded in v1 | O31: High | P31: NCVBDC + peer-reviewed acoustic studies | Q31: Not recorded in v1 | R31: Not recorded in v1 | S31: https://academic.oup.com/aesa/article/115/1/113/6409746 | T31: v1 (33-row) | U31: Important malaria vector in India.
A32: R031 | B32: Anopheles stephensi | C32: Anopheles | D32: Male | E32: Yes | F32: 640 | G32: 640 | H32: 640 | J32: Published value | K32: Not recorded in v1 | L32: Established vector | M32: Malaria | N32: Not recorded in v1 | O32: High | P32: Peer-reviewed acoustic studies | Q32: Not recorded in v1 | R32: Not recorded in v1 | S32: https://academic.oup.com/aesa/article/115/1/113/6409746 | T32: v1 (33-row) | U32: Male reference frequency.
A33: R032 | B33: Anopheles stephensi | C33: Anopheles | D33: Not reported | E33: No | J33: Not found | K33: Not found | L33: Established vector | M33: Malaria | N33: Yes - primary urban malaria vector in India (per S12, which cites Tamil Nadu, India breeding-site literature); also confirmed refractory (NOT competent) for Zika virus (S9) | O33: HIGH | P33: Not found - no acoustic/wingbeat frequency study located for this species in this research pass | Q33: 2021 | R33: 10.3201/eid2702.200019 (pattern-based, not independently confirmed) | S33: https://wwwnc.cdc.gov/eid/article/27/2/20-0019_article | T33: v2 (26-row) | U33: India-specific vector role is well-established in the broader literature (An. stephensi is the principal urban/peri-urban malaria vector in Indian cities), but the specific field-infection citation retrieved in this pass (S11) is from Ethiopia, not India; India relevance here is supported by S12's citation of Tamil Nadu breeding studies rather than direct India infection data.
A34: R033 | B34: Anopheles subpictus | C34: Anopheles | D34: Female | E34: Yes | F34: 445.46 | G34: 445.46 | H34: 445.46 | I34: 2.01 | J34: Mean ± SD | K34: Not recorded in v1 | L34: Documented vector / regional association | M34: Malaria; Japanese encephalitis association reported in Indian surveillance literature | N34: Not recorded in v1 | O34: Medium | P34: 2024 India acoustic study + NCVBDC | Q34: Not recorded in v1 | R34: Not recorded in v1 | S34: https://www.sciencedirect.com/science/article/pii/S0001706X24001049 | T34: v1 (33-row) | U34: Disease role is geography-specific.
A35: R034 | B35: Anopheles subpictus | C35: Anopheles | D35: Female | E35: Yes | H35: 445.46 | I35: 2.01 | J35: Fundamental frequency (F0) | K35: India field-collected, sound-recording device (Mandal et al. 2024) | L35: Evidence insufficient | M35: Not found | N35: Species recorded in India (S1); this species is widely discussed in the literature as a secondary/potential malaria vector in parts of India, but that claim is NOT included here because it was not independently verified with a primary source in this research pass | O35: MEDIUM | P35: Mandal et al. 2024 (Acta Tropica, S1) | Q35: 2024 | R35: 38642695 | S35: https://www.sciencedirect.com/science/article/abs/pii/S0001706X24001049 | T35: v2 (26-row) | U35: nan
A36: R035 | B36: Armigeres subalbatus | C36: Armigeres | D36: Female | E36: Yes | F36: 347.47 | G36: 369.64 | H36: 358.21 | J36: Range + mean | K36: Not recorded in v1 | L36: Documented/experimental vector evidence | M36: Vector involvement reported for some filarial/arboviral systems | N36: Not recorded in v1 | O36: Medium | P36: 2025 India acoustic study + vector literature | Q36: Not recorded in v1 | R36: Not recorded in v1 | S36: https://pmc.ncbi.nlm.nih.gov/articles/PMC12049413/ | T36: v1 (33-row) | U36: Do not collapse experimental competence and epidemiological importance into yes/no.
A37: R036 | B37: Culex alienus | C37: Culex | D37: Female | E37: Yes | F37: 539.44 | G37: 539.44 | H37: 539.44 | I37: 0.63 | J37: Mean ± SD | K37: Not recorded in v1 | L37: No major human-disease vector role identified | M37: No major human-disease vector association identified in reviewed sources | N37: Not recorded in v1 | O37: Medium | P37: 2024 India acoustic study | Q37: Not recorded in v1 | R37: Not recorded in v1 | S37: https://www.sciencedirect.com/science/article/pii/S0001706X24001049 | T37: v1 (33-row) | U37: Included primarily as an acoustic reference species.
A38: R037 | B38: Culex alienus | C38: Culex | D38: Female | E38: Yes | H38: 539.44 | I38: 0.629 | J38: Fundamental frequency (F0) | K38: India field-collected, sound-recording device (Mandal et al. 2024) | L38: Evidence insufficient | M38: Not found | N38: Species recorded in India (S1); disease/vector role not verified in this research pass | O38: MEDIUM | P38: Mandal et al. 2024 (Acta Tropica, S1) | Q38: 2024 | R38: 38642695 | S38: https://www.sciencedirect.com/science/article/abs/pii/S0001706X24001049 | T38: v2 (26-row) | U38: nan
A39: R038 | B39: Culex bitaeniorhynchus | C39: Culex | D39: Not reported | E39: No | J39: Not found | K39: Not found | L39: Documented vector | M39: Japanese encephalitis | N39: Yes - named as a JE vector in an Indian field vector-composition study | O39: MEDIUM | P39: Not found - no acoustic/wingbeat frequency study located for this species in this research pass | Q39: 2011 | R39: Not confirmed | S39: https://pmc.ncbi.nlm.nih.gov/articles/PMC4017167/ | T39: v2 (26-row) | U39: No wingbeat/acoustic frequency data located for this species in this research pass - do not infer a value from congeners.
A40: R039 | B40: Culex gelidus | C40: Culex | D40: Female | E40: Yes | F40: 426.56 | G40: 426.56 | H40: 426.56 | I40: 8.53 | J40: Mean ± SD | K40: Not recorded in v1 | L40: Documented/secondary vector | M40: Japanese encephalitis | N40: Not recorded in v1 | O40: High | P40: 2024 India acoustic study + NCVBDC | Q40: Not recorded in v1 | R40: Not recorded in v1 | S40: https://www.sciencedirect.com/science/article/pii/S0001706X24001049 | T40: v1 (33-row) | U40: Regional importance varies.
...

Sheet Species_Summary
A1: Species_Name | B1: Sex | C1: Source_Rows | D1: Rows_With_Frequency | E1: Lowest_Reported_Hz | F1: Highest_Reported_Hz | G1: Spread_Hz | H1: In_Versions
A2: Aedes aegypti | B2: Female | C2: =COUNTIFS(Consolidated!$B$2:$B$60,$A2,Consolidated!$D$2:$D$60,$B2) -> 4 | D2: =COUNTIFS(Consolidated!$B$2:$B$60,$A2,Consolidated!$D$2:$D$60,$B2,Consolidated!$E$2:$E$60,"Yes") -> 4 | E2: =IF(COUNTIFS(Consolidated!$B$2:$B$60,$A2,Consolidated!$D$2:$D$60,$B2,Consolidated!$F$2:$F$60,">0")=0,"",_xlfn.MINIFS(Consolidated!$F$2:$F$60,Consolidated!$B$2:$B$60,$A2,Consolidated!$D$2:$D$60,$B2,Consolidated!$F$2:$F$60,">0")) -> 460 | F2: =IF(COUNTIFS(Consolidated!$B$2:$B$60,$A2,Consolidated!$D$2:$D$60,$B2,Consolidated!$F$2:$F$60,">0")=0,"",_xlfn.MAXIFS(Consolidated!$G$2:$G$60,Consolidated!$B$2:$B$60,$A2,Consolidated!$D$2:$D$60,$B2)) -> 664 | G2: =IFERROR(IF(AND(ISNUMBER($E2),ISNUMBER($F2)),$F2-$E2,""),"") -> 204 | H2: v1 (33-row) + v2 (26-row)
A3: Aedes aegypti | B3: Male | C3: =COUNTIFS(Consolidated!$B$2:$B$60,$A3,Consolidated!$D$2:$D$60,$B3) -> 2 | D3: =COUNTIFS(Consolidated!$B$2:$B$60,$A3,Consolidated!$D$2:$D$60,$B3,Consolidated!$E$2:$E$60,"Yes") -> 2 | E3: =IF(COUNTIFS(Consolidated!$B$2:$B$60,$A3,Consolidated!$D$2:$D$60,$B3,Consolidated!$F$2:$F$60,">0")=0,"",_xlfn.MINIFS(Consolidated!$F$2:$F$60,Consolidated!$B$2:$B$60,$A3,Consolidated!$D$2:$D$60,$B3,Consolidated!$F$2:$F$60,">0")) -> 711 | F3: =IF(COUNTIFS(Consolidated!$B$2:$B$60,$A3,Consolidated!$D$2:$D$60,$B3,Consolidated!$F$2:$F$60,">0")=0,"",_xlfn.MAXIFS(Consolidated!$G$2:$G$60,Consolidated!$B$2:$B$60,$A3,Consolidated!$D$2:$D$60,$B3)) -> 982 | G3: =IFERROR(IF(AND(ISNUMBER($E3),ISNUMBER($F3)),$F3-$E3,""),"") -> 271 | H3: v1 (33-row) + v2 (26-row)
A4: Aedes albopictus | B4: Female | C4: =COUNTIFS(Consolidated!$B$2:$B$60,$A4,Consolidated!$D$2:$D$60,$B4) -> 2 | D4: =COUNTIFS(Consolidated!$B$2:$B$60,$A4,Consolidated!$D$2:$D$60,$B4,Consolidated!$E$2:$E$60,"Yes") -> 2 | E4: =IF(COUNTIFS(Consolidated!$B$2:$B$60,$A4,Consolidated!$D$2:$D$60,$B4,Consolidated!$F$2:$F$60,">0")=0,"",_xlfn.MINIFS(Consolidated!$F$2:$F$60,Consolidated!$B$2:$B$60,$A4,Consolidated!$D$2:$D$60,$B4,Consolidated!$F$2:$F$60,">0")) -> 462 | F4: =IF(COUNTIFS(Consolidated!$B$2:$B$60,$A4,Consolidated!$D$2:$D$60,$B4,Consolidated!$F$2:$F$60,">0")=0,"",_xlfn.MAXIFS(Consolidated!$G$2:$G$60,Consolidated!$B$2:$B$60,$A4,Consolidated!$D$2:$D$60,$B4)) -> 544 | G4: =IFERROR(IF(AND(ISNUMBER($E4),ISNUMBER($F4)),$F4-$E4,""),"") -> 82 | H4: v1 (33-row) + v2 (26-row)
A5: Aedes albopictus | B5: Male | C5: =COUNTIFS(Consolidated!$B$2:$B$60,$A5,Consolidated!$D$2:$D$60,$B5) -> 1 | D5: =COUNTIFS(Consolidated!$B$2:$B$60,$A5,Consolidated!$D$2:$D$60,$B5,Consolidated!$E$2:$E$60,"Yes") -> 1 | E5: =IF(COUNTIFS(Consolidated!$B$2:$B$60,$A5,Consolidated!$D$2:$D$60,$B5,Consolidated!$F$2:$F$60,">0")=0,"",_xlfn.MINIFS(Consolidated!$F$2:$F$60,Consolidated!$B$2:$B$60,$A5,Consolidated!$D$2:$D$60,$B5,Consolidated!$F$2:$F$60,">0")) -> 724 | F5: =IF(COUNTIFS(Consolidated!$B$2:$B$60,$A5,Consolidated!$D$2:$D$60,$B5,Consolidated!$F$2:$F$60,">0")=0,"",_xlfn.MAXIFS(Consolidated!$G$2:$G$60,Consolidated!$B$2:$B$60,$A5,Consolidated!$D$2:$D$60,$B5)) -> 903 | G5: =IFERROR(IF(AND(ISNUMBER($E5),ISNUMBER($F5)),$F5-$E5,""),"") -> 179 | H5: v1 (33-row)
A6: Aedes vittatus | B6: Female | C6: =COUNTIFS(Consolidated!$B$2:$B$60,$A6,Consolidated!$D$2:$D$60,$B6) -> 2 | D6: =COUNTIFS(Consolidated!$B$2:$B$60,$A6,Consolidated!$D$2:$D$60,$B6,Consolidated!$E$2:$E$60,"Yes") -> 2 | E6: =IF(COUNTIFS(Consolidated!$B$2:$B$60,$A6,Consolidated!$D$2:$D$60,$B6,Consolidated!$F$2:$F$60,">0")=0,"",_xlfn.MINIFS(Consolidated!$F$2:$F$60,Consolidated!$B$2:$B$60,$A6,Consolidated!$D$2:$D$60,$B6,Consolidated!$F$2:$F$60,">0")) -> 567.51 | F6: =IF(COUNTIFS(Consolidated!$B$2:$B$60,$A6,Consolidated!$D$2:$D$60,$B6,Consolidated!$F$2:$F$60,">0")=0,"",_xlfn.MAXIFS(Consolidated!$G$2:$G$60,Consolidated!$B$2:$B$60,$A6,Consolidated!$D$2:$D$60,$B6)) -> 567.51 | G6: =IFERROR(IF(AND(ISNUMBER($E6),ISNUMBER($F6)),$F6-$E6,""),"") -> 0 | H6: v1 (33-row) + v2 (26-row)
A7: Anopheles albimanus | B7: Female | C7: =COUNTIFS(Consolidated!$B$2:$B$60,$A7,Consolidated!$D$2:$D$60,$B7) -> 1 | D7: =COUNTIFS(Consolidated!$B$2:$B$60,$A7,Consolidated!$D$2:$D$60,$B7,Consolidated!$E$2:$E$60,"Yes") -> 1 | E7: =IF(COUNTIFS(Consolidated!$B$2:$B$60,$A7,Consolidated!$D$2:$D$60,$B7,Consolidated!$F$2:$F$60,">0")=0,"",_xlfn.MINIFS(Consolidated!$F$2:$F$60,Consolidated!$B$2:$B$60,$A7,Consolidated!$D$2:$D$60,$B7,Consolidated!$F$2:$F$60,">0")) -> 369 | F7: =IF(COUNTIFS(Consolidated!$B$2:$B$60,$A7,Consolidated!$D$2:$D$60,$B7,Consolidated!$F$2:$F$60,">0")=0,"",_xlfn.MAXIFS(Consolidated!$G$2:$G$60,Consolidated!$B$2:$B$60,$A7,Consolidated!$D$2:$D$60,$B7)) -> 430 | G7: =IFERROR(IF(AND(ISNUMBER($E7),ISNUMBER($F7)),$F7-$E7,""),"") -> 61 | H7: v1 (33-row)
A8: Anopheles albimanus | B8: Male | C8: =COUNTIFS(Consolidated!$B$2:$B$60,$A8,Consolidated!$D$2:$D$60,$B8) -> 1 | D8: =COUNTIFS(Consolidated!$B$2:$B$60,$A8,Consolidated!$D$2:$D$60,$B8,Consolidated!$E$2:$E$60,"Yes") -> 1 | E8: =IF(COUNTIFS(Consolidated!$B$2:$B$60,$A8,Consolidated!$D$2:$D$60,$B8,Consolidated!$F$2:$F$60,">0")=0,"",_xlfn.MINIFS(Consolidated!$F$2:$F$60,Consolidated!$B$2:$B$60,$A8,Consolidated!$D$2:$D$60,$B8,Consolidated!$F$2:$F$60,">0")) -> 524 | F8: =IF(COUNTIFS(Consolidated!$B$2:$B$60,$A8,Consolidated!$D$2:$D$60,$B8,Consolidated!$F$2:$F$60,">0")=0,"",_xlfn.MAXIFS(Consolidated!$G$2:$G$60,Consolidated!$B$2:$B$60,$A8,Consolidated!$D$2:$D$60,$B8)) -> 714 | G8: =IFERROR(IF(AND(ISNUMBER($E8),ISNUMBER($F8)),$F8-$E8,""),"") -> 190 | H8: v1 (33-row)
A9: Anopheles annularis | B9: Not reported | C9: =COUNTIFS(Consolidated!$B$2:$B$60,$A9,Consolidated!$D$2:$D$60,$B9) -> 1 | D9: =COUNTIFS(Consolidated!$B$2:$B$60,$A9,Consolidated!$D$2:$D$60,$B9,Consolidated!$E$2:$E$60,"Yes") -> 0 | E9: =IF(COUNTIFS(Consolidated!$B$2:$B$60,$A9,Consolidated!$D$2:$D$60,$B9,Consolidated!$F$2:$F$60,">0")=0,"",_xlfn.MINIFS(Consolidated!$F$2:$F$60,Consolidated!$B$2:$B$60,$A9,Consolidated!$D$2:$D$60,$B9,Consolidated!$F$2:$F$60,">0")) | F9: =IF(COUNTIFS(Consolidated!$B$2:$B$60,$A9,Consolidated!$D$2:$D$60,$B9,Consolidated!$F$2:$F$60,">0")=0,"",_xlfn.MAXIFS(Consolidated!$G$2:$G$60,Consolidated!$B$2:$B$60,$A9,Consolidated!$D$2:$D$60,$B9)) | G9: =IFERROR(IF(AND(ISNUMBER($E9),ISNUMBER($F9)),$F9-$E9,""),"") | H9: v2 (26-row)
A10: Anopheles arabiensis | B10: Female | C10: =COUNTIFS(Consolidated!$B$2:$B$60,$A10,Consolidated!$D$2:$D$60,$B10) -> 1 | D10: =COUNTIFS(Consolidated!$B$2:$B$60,$A10,Consolidated!$D$2:$D$60,$B10,Consolidated!$E$2:$E$60,"Yes") -> 1 | E10: =IF(COUNTIFS(Consolidated!$B$2:$B$60,$A10,Consolidated!$D$2:$D$60,$B10,Consolidated!$F$2:$F$60,">0")=0,"",_xlfn.MINIFS(Consolidated!$F$2:$F$60,Consolidated!$B$2:$B$60,$A10,Consolidated!$D$2:$D$60,$B10,Consolidated!$F$2:$F$60,">0")) -> 489 | F10: =IF(COUNTIFS(Consolidated!$B$2:$B$60,$A10,Consolidated!$D$2:$D$60,$B10,Consolidated!$F$2:$F$60,">0")=0,"",_xlfn.MAXIFS(Consolidated!$G$2:$G$60,Consolidated!$B$2:$B$60,$A10,Consolidated!$D$2:$D$60,$B10)) -> 489 | G10: =IFERROR(IF(AND(ISNUMBER($E10),ISNUMBER($F10)),$F10-$E10,""),"") -> 0 | H10: v1 (33-row)
A11: Anopheles arabiensis | B11: Male | C11: =COUNTIFS(Consolidated!$B$2:$B$60,$A11,Consolidated!$D$2:$D$60,$B11) -> 1 | D11: =COUNTIFS(Consolidated!$B$2:$B$60,$A11,Consolidated!$D$2:$D$60,$B11,Consolidated!$E$2:$E$60,"Yes") -> 1 | E11: =IF(COUNTIFS(Consolidated!$B$2:$B$60,$A11,Consolidated!$D$2:$D$60,$B11,Consolidated!$F$2:$F$60,">0")=0,"",_xlfn.MINIFS(Consolidated!$F$2:$F$60,Consolidated!$B$2:$B$60,$A11,Consolidated!$D$2:$D$60,$B11,Consolidated!$F$2:$F$60,">0")) -> 763 | F11: =IF(COUNTIFS(Consolidated!$B$2:$B$60,$A11,Consolidated!$D$2:$D$60,$B11,Consolidated!$F$2:$F$60,">0")=0,"",_xlfn.MAXIFS(Consolidated!$G$2:$G$60,Consolidated!$B$2:$B$60,$A11,Consolidated!$D$2:$D$60,$B11)) -> 763 | G11: =IFERROR(IF(AND(ISNUMBER($E11),ISNUMBER($F11)),$F11-$E11,""),"") -> 0 | H11: v1 (33-row)
A12: Anopheles barbirostris | B12: Not reported | C12: =COUNTIFS(Consolidated!$B$2:$B$60,$A12,Consolidated!$D$2:$D$60,$B12) -> 1 | D12: =COUNTIFS(Consolidated!$B$2:$B$60,$A12,Consolidated!$D$2:$D$60,$B12,Consolidated!$E$2:$E$60,"Yes") -> 0 | E12: =IF(COUNTIFS(Consolidated!$B$2:$B$60,$A12,Consolidated!$D$2:$D$60,$B12,Consolidated!$F$2:$F$60,">0")=0,"",_xlfn.MINIFS(Consolidated!$F$2:$F$60,Consolidated!$B$2:$B$60,$A12,Consolidated!$D$2:$D$60,$B12,Consolidated!$F$2:$F$60,">0")) | F12: =IF(COUNTIFS(Consolidated!$B$2:$B$60,$A12,Consolidated!$D$2:$D$60,$B12,Consolidated!$F$2:$F$60,">0")=0,"",_xlfn.MAXIFS(Consolidated!$G$2:$G$60,Consolidated!$B$2:$B$60,$A12,Consolidated!$D$2:$D$60,$B12)) | G12: =IFERROR(IF(AND(ISNUMBER($E12),ISNUMBER($F12)),$F12-$E12,""),"") | H12: v2 (26-row)
A13: Anopheles crawfordi | B13: Female | C13: =COUNTIFS(Consolidated!$B$2:$B$60,$A13,Consolidated!$D$2:$D$60,$B13) -> 1 | D13: =COUNTIFS(Consolidated!$B$2:$B$60,$A13,Consolidated!$D$2:$D$60,$B13,Consolidated!$E$2:$E$60,"Yes") -> 1 | E13: =IF(COUNTIFS(Consolidated!$B$2:$B$60,$A13,Consolidated!$D$2:$D$60,$B13,Consolidated!$F$2:$F$60,">0")=0,"",_xlfn.MINIFS(Consolidated!$F$2:$F$60,Consolidated!$B$2:$B$60,$A13,Consolidated!$D$2:$D$60,$B13,Consolidated!$F$2:$F$60,">0")) -> 295.29 | F13: =IF(COUNTIFS(Consolidated!$B$2:$B$60,$A13,Consolidated!$D$2:$D$60,$B13,Consolidated!$F$2:$F$60,">0")=0,"",_xlfn.MAXIFS(Consolidated!$G$2:$G$60,Consolidated!$B$2:$B$60,$A13,Consolidated!$D$2:$D$60,$B13)) -> 338.29 | G13: =IFERROR(IF(AND(ISNUMBER($E13),ISNUMBER($F13)),$F13-$E13,""),"") -> 43 | H13: v1 (33-row)
... A46: Uranotaenia lowii | B46: Not reported | C46: =COUNTIFS(Consolidated!$B$2:$B$60,$A46,Consolidated!$D$2:$D$60,$B46) -> 1 | D46: =COUNTIFS(Consolidated!$B$2:$B$60,$A46,Consolidated!$D$2:$D$60,$B46,Consolidated!$E$2:$E$60,"Yes") -> 1 | E46: =IF(COUNTIFS(Consolidated!$B$2:$B$60,$A46,Consolidated!$D$2:$D$60,$B46,Consolidated!$F$2:$F$60,">0")=0,"",_xlfn.MINIFS(Consolidated!$F$2:$F$60,Consolidated!$B$2:$B$60,$A46,Consolidated!$D$2:$D$60,$B46,Consolidated!$F$2:$F$60,">0")) | F46: =IF(COUNTIFS(Consolidated!$B$2:$B$60,$A46,Consolidated!$D$2:$D$60,$B46,Consolidated!$F$2:$F$60,">0")=0,"",_xlfn.MAXIFS(Consolidated!$G$2:$G$60,Consolidated!$B$2:$B$60,$A46,Consolidated!$D$2:$D$60,$B46)) | G46: =IFERROR(IF(AND(ISNUMBER($E46),ISNUMBER($F46)),$F46-$E46,""),"") | H46: v2 (26-row)
A48: Min/max are drawn ONLY from the Freq_Min_Hz and Freq_Max_Hz columns on Consolidated. Rows carrying a single mean with no range contribute nothing here — check the Consolidated sheet for those. Blank means no range was reported for that species/sex in either source file.

Sheet Sources
A1: Source_ID | B1: Source_Name | C1: Source_Title | D1: URL | E1: Information_Used_For | F1: From_Version
A2: S01 | B2: WHO | C2: Vector-borne diseases | D2: https://www.who.int/en/news-room/fact-sheets/detail/vector-borne-diseases | E2: Disease/vector genus-level associations | F2: v1 (33-row)
A3: S02 | B3: CDC | C3: About Mosquitoes | D3: https://www.cdc.gov/mosquitoes/about/index.html | E3: General mosquito/vector fundamentals | F3: v1 (33-row)
A4: S03 | B4: Mandal et al., Acta Tropica (2024) | C4: Surveillance of mosquitoes harnessing their buzzing sound | D4: https://pubmed.ncbi.nlm.nih.gov/38642695/ | E4: India-based acoustic measurements across multiple mosquito species | F4: v1 (33-row)
A5: S04 | B5: Annals of the Entomological Society of America | C5: Mosquito wingbeat frequency reference compilation | D5: https://academic.oup.com/aesa/article/115/1/113/6409746 | E5: Published male/female fundamental frequency values | F5: v1 (33-row)
A6: S05 | B6: Scientific Reports (2021) | C6: Infrared light sensors permit rapid recording of wingbeat frequency and bioacoustic species identification of mosquitoes | D6: https://www.nature.com/articles/s41598-021-89644-z | E6: 29-species acoustic dataset; demonstrates frequency overlap | F6: v1 (33-row)
A7: S06 | B7: Scientific Reports (2025) | C7: India acoustic study on age/activity-related wingbeat variation | D7: https://www.nature.com/articles/s41598-025-89608-7 | E7: Shows frequency changes with age/physiological state | F7: v1 (33-row)
A8: S07 | B8: NCVBDC, Government of India | C8: Japanese encephalitis vector information | D8: https://ncvbdc.mohfw.gov.in/index1.php?Background=Dark&lang=1&level=2&lid=3756&sublinkid=5923 | E8: Indian vector information for JE | F8: v1 (33-row)
A9: S08 | B9: NCVBDC, Government of India | C9: Malaria vector documentation | D9: https://www.ncvbdc.mohfw.gov.in/WriteReadData/l892s/5232542721532941542.pdf | E9: Indian malaria vector species | F9: v1 (33-row)
A10: S09 | B10: NCVBDC, Government of India | C10: Enhanced LF guideline (2024) | D10: https://ncvbdc.mohfw.gov.in/Doc/Guidelines/Fil/ELF-Guideline-2024.pdf | E10: Indian lymphatic filariasis vector information | F10: v1 (33-row)
A11: S10 | B11: PubMed / vector competence literature | C11: Aedes vittatus vector competence | D11: https://pubmed.ncbi.nlm.nih.gov/34472507/ | E11: Experimental vector competence context | F11: v1 (33-row)
A12: S1 | B12: Acta Tropica (Elsevier) | C12: Surveillance of mosquitoes harnessing their buzzing sound | D12: https://www.sciencedirect.com/science/article/abs/pii/S0001706X24001049 | E12: Female fundamental frequency (F0) for 9 of 19 Indian mosquito species named in the published abstract (full 19-species table is paywalled; not accessible in this pass) | F12: v2 (26-row)
... A24: S13 | B24: Indexed on PubMed Central (journal name not confirmed in this pass) | C24: Lymphatic filariasis, infection status in Culex quinquefasciatus and Anopheles species after six rounds of mass drug administration in Masasi District, Tanzania | D24: https://www.ncbi.nlm.nih.gov/pmc/articles/PMC7919328/ | E24: Confirms Cx. quinquefasciatus as dominant filarial vector (99.2% of vector mosquitoes collected) and PCR-positive for Wuchereria bancrofti - Tanzania, not India, used as general vector-competence evidence | F24: v2 (26-row)

Sheet Readme
A1: VectorGate — consolidated mosquito acoustic reference
A3: 1. What the five uploaded files actually were
A4: mosquito_acoustic_disease_reference.xlsx and __1_.xlsx are byte-for-byte identical duplicates (same MD5). The .csv of the same name is just the Mosquito_Dataset sheet of that workbook exported. So three of the five files are one dataset: 33 rows, 15 columns. Call it v1.
A5: mosquito_acoustic_disease_reference__2_.xlsx and its .csv are the other dataset: 26 rows, 28 columns. Call it v2.
A6: Only 11 species/sex combinations appear in both. v1 has 22 combinations v2 lacks; v2 has 13 v1 lacks.
A8: 2. How v1 and v2 differ
A9: v1 is broader but thinly sourced. It covers African and American vectors (An. gambiae, An. arabiensis, An. darlingi, Cx. tarsalis) and gives a numeric frequency for every single row. But most rows cite the same generic review URL, there are no DOIs, PMIDs or study years, and no measurement conditions. The numbers look like values compiled from a secondary review rather than traced to a primary measurement.
A10: v2 is narrower but far better sourced. It carries DOI, PMID, study year, measurement conditions, frequency type (fundamental vs mean wingbeat), geographic context and an explicit India_Relevance column. It also refuses to guess: 12 of its 26 rows say "Not found" for frequency and "Not reported" for sex rather than filling a plausible number.
A11: Where they overlap they disagree, and the disagreement is real rather than an error. Aedes aegypti female appears as 460-664 Hz in v1 and as three separate source-specific rows in v2: 463.07 Hz (India, Mandal 2024), 498.1 Hz (US lab colony at 23 C, Kim 2021) and 664.0 Hz (Thailand free-flight swarm at 32.6 C, Cator 2011). None is wrong. They are different populations under different conditions measured different ways.
A13: 3. What this consolidated file does
A14: Consolidated sheet: every row from both versions, normalised onto one column set, with a From_Version column so you can always tell which file a row came from, and a Has_Frequency flag (highlighted amber where No). Source-specific rows are deliberately NOT averaged together — that would destroy the information described above.
A15: Species_Summary sheet: per species and sex, how many source rows exist, how many carry a frequency, and the lowest and highest reported bounds. Computed with formulas off the Consolidated sheet, so it updates if you add rows.
... A28: That is the strongest evidence you have for the multi-feature argument, and it comes from the literature rather than from you. Verify both figures against the primary papers before putting them on a slide.
